<?xml version="1.0"?>
<robot xmlns:xacro="http://www.ros.org/wiki/xacro">

    <xacro:macro name="solo12_quadruped" params="prefix">

        <!--The root link ${prefix}base_link has an inertia specified in 
            the URDF, but KDL does not support a root link with an inertia.  
            As a workaround, you can add an extra dummy link to your URDF.-->
        <link name="world" />
        <joint name="world_joint" type="fixed">
            <parent link="world" />
            <child link="${prefix}base_link" />
            <origin rpy="0 0 0" xyz="0 0 0" />
        </joint>
        <link name="${prefix}base_link">
            <!-- BASE LINK INERTIAL -->
            <inertial>
                <origin rpy="0 0 0" xyz="0 0 0" />
                <mass value="1.16115091" />
                <!-- The base is extremely symmetrical. -->
                <inertia ixx="0.00578574" ixy="0.0" ixz="0.0" iyy="0.01938108" iyz="0.0"
                    izz="0.02476124" />
            </inertial>
            <!-- BASE LINK VISUAL -->
            <visual>
                <origin rpy="0 0 0" xyz="0 0 0" />
                <geometry>
                    <mesh
                        filename="file://$(find solo12_description)/meshes/stl/solo12/solo_12_base.stl" />
                </geometry>
                <material name="grey">
                    <color rgba="0.8 0.8 0.8 1.0" />
                </material>
            </visual>
            <!-- BASE LINK COLLISION -->
            <collision>
                <origin rpy="0 0 0" xyz="0 0 0" />
                <geometry>
                    <mesh
                        filename="file://$(find solo12_description)/meshes/stl/solo12/solo_12_base.stl" />
                </geometry>
                <material name="grey">
                    <color rgba="0.8 0.8 0.8 1.0" />
                </material>
            </collision>
            <!-- Bullet specific paramters -->
            <contact>
                <lateral_friction value="1.0" />
                <restitution value="0.5" />
            </contact>
        </link>
        <!-- END BASE LINK -->

        <joint name="${prefix}FL_HAA" type="revolute">
            <parent link="${prefix}base_link" />
            <child link="${prefix}FL_SHOULDER" />
            <limit effort="1000" lower="-10" upper="10" velocity="1000" />
            <!-- joints rotates around the x-axis -->
            <axis xyz="1 0 0" />
            <origin rpy="0 0 0" xyz="0.1946 0.0875 0" />
            <!-- pybullet simulation parameters -->
            <dynamics damping="0.0" friction="0.0" />
        </joint>

        <link name="${prefix}FL_SHOULDER">
            <!-- TODO: Update inertias. -->
            <!-- create a dummy shoulder link to join the two joints -->
            <!-- HAA VISUAL -->
            <visual>
                <origin rpy="0 0 0" xyz="0.01950 0 0" />
                <geometry>
                    <mesh
                        filename="file://$(find solo12_description)/meshes/stl/solo12/solo12_hip_fe_fl.stl" />
                </geometry>
                <material name="grey">
                    <color rgba="0.8 0.8 0.8 1.0" />
                </material>
            </visual>
            <!-- HAA LINK COLLISION -->
            <collision>
                <origin rpy="0 0 0" xyz="0.01950 0 0" />
                <geometry>
                    <mesh
                        filename="file://$(find solo12_description)/meshes/stl/solo12/solo12_hip_fe_fl.stl" />
                </geometry>
                <material name="grey">
                    <color rgba="0.8 0.8 0.8 1.0" />
                </material>
            </collision>
            <inertial>
                <mass value="0.14853845" />
                <!-- HAA body inertia -->
                <origin rpy="0 0 0" xyz="-0.07870700 0.01 0." />
                <inertia ixx="0.00003024" ixy="0.00004671" ixz="0.0" iyy="0.00041193" iyz="0.0"
                    izz="0.00041107" />
            </inertial>
        </link>

        <joint name="${prefix}FL_HFE" type="revolute">
            <parent link="${prefix}FL_SHOULDER" />
            <child link="${prefix}FL_UPPER_LEG" />
            <limit effort="1000" lower="-10" upper="10" velocity="1000" />
            <!-- joints rotates around the y-axis -->
            <axis xyz="0 1 0" />
            <origin rpy="0 0 0" xyz="0 0.014 0" />
            <!-- pybullet simulation parameters -->
            <dynamics damping="0.0" friction="0.0" />
        </joint>

        <link name="${prefix}FL_UPPER_LEG">
            <!-- Left upper leg inertia -->
            <inertial>
                <origin rpy="0 0 0" xyz="0.00001377 0.01935853 -0.07870700" />
                <mass value="0.14853845" />
                <inertia ixx="0.00041107" ixy="0.0" ixz="0.0" iyy="0.00041193" iyz="0.00004671"
                    izz="0.00003024" />
            </inertial>
            <!-- UPPER LEG LINK VISUAL -->
            <visual>
                <origin rpy="0 0 0" xyz="0 0 0" />
                <geometry>
                    <mesh
                        filename="file://$(find solo12_description)/meshes/stl/with_foot/solo_upper_leg_left_side.stl" />
                </geometry>
                <material name="grey">
                    <color rgba="0.8 0.8 0.8 1.0" />
                </material>
            </visual>
            <!-- UPPER LEG LINK COLLISION -->
            <collision>
                <origin rpy="0 0 0" xyz="0 0 0" />
                <geometry>
                    <mesh
                        filename="file://$(find solo12_description)/meshes/stl/with_foot/solo_upper_leg_left_side.stl" />
                </geometry>
                <material name="grey">
                    <color rgba="0.8 0.8 0.8 1.0" />
                </material>
            </collision>
            <!-- Bullet specific paramters -->
            <contact>
                <lateral_friction value="1.0" />
                <restitution value="0.5" />
            </contact>
        </link>
        <!-- END UPPER LEG LINK -->

        <!-- KFE: Joint between the upper leg and the lower leg -->
        <joint name="${prefix}FL_KFE" type="revolute">
            <parent link="${prefix}FL_UPPER_LEG" />
            <child link="${prefix}FL_LOWER_LEG" />
            <limit effort="1000" lower="-10" upper="10" velocity="1000" />
            <!-- joints rotates around the y-axis -->
            <axis xyz="0 1 0" />
            <origin rpy="0 0 0" xyz="0 0.03745 -0.16" />
            <!-- pybullet simulation parameters -->
            <dynamics damping="0.0" friction="0.0" />
        </joint>

        <link name="${prefix}FL_LOWER_LEG">
            <!-- Left lower leg inertia -->
            <inertial>
                <origin rpy="0 0 0" xyz="0.0 0.00787644 -0.08928215" />
                <mass value="0.03070001" />
                <inertia ixx="0.00012024" ixy="0.0" ixz="0.0" iyy="0.00012029" iyz="0.00000305"
                    izz="0.00000216" />
            </inertial>
            <!-- LOWER LEG LINK VISUAL -->
            <visual>
                <origin rpy="0 0 0" xyz="0 0 0" />
                <geometry>
                    <mesh
                        filename="file://$(find solo12_description)/meshes/stl/with_foot/solo_lower_leg_left_side.stl" />
                </geometry>
                <material name="grey">
                    <color rgba="0.8 0.8 0.8 1.0" />
                </material>
            </visual>
            <!-- LOWER LEG LINK COLLISION -->
            <collision>
                <origin rpy="0 0 0" xyz="0 0 0" />
                <geometry>
                    <mesh
                        filename="file://$(find solo12_description)/meshes/stl/with_foot/solo_lower_leg_left_side.stl" />
                </geometry>
                <material name="grey">
                    <color rgba="0.8 0.8 0.8 1.0" />
                </material>
            </collision>
            <!-- Bullet specific paramters -->
            <contact>
                <lateral_friction value="1.0" />
                <restitution value="0.5" />
            </contact>
        </link>
        <!-- END LOWER LEG LINK -->

        <!-- KFE: Joint between the upper leg and the lower leg -->
        <joint name="${prefix}FL_ANKLE" type="fixed">
            <parent link="${prefix}FL_LOWER_LEG" />
            <child link="${prefix}FL_FOOT" />
            <origin rpy="0 0 0" xyz="0 0.008 -0.16" />
            <!-- Limits (usefull?) -->
            <limit effort="1000" lower="-10" upper="10" velocity="1000" />
            <!-- pybullet simulation parameters -->
            <dynamics damping="0.0" friction="0.0" />
        </joint>

        <link name="${prefix}FL_FOOT">
            <!-- FOOT INERTIAL -->
            <!-- This link is symmetrical left or right -->
            <inertial>
                <origin rpy="0 0 0" xyz="0 0 0.00035767" />
                <mass value="0.00693606" />
                <inertia ixx="0.00000057" ixy="0.0" ixz="0.0" iyy="0.00000084" iyz="0.0"
                    izz="0.00000053" />
            </inertial>
            <!-- FOOT VISUAL -->
            <visual>
                <origin rpy="0 0 0" xyz="0 0 0" />
                <geometry>
                    <mesh
                        filename="file://$(find solo12_description)/meshes/stl/with_foot/solo_foot.stl" />
                </geometry>
                <material name="grey">
                    <color rgba="0.8 0.8 0.8 1.0" />
                </material>
            </visual>
            <!-- FOOT COLLISION -->
            <collision>
                <origin rpy="0 0 0" xyz="0 0 0" />
                <geometry>
                    <mesh
                        filename="file://$(find solo12_description)/meshes/stl/with_foot/solo_foot.stl" />
                </geometry>
                <material name="grey">
                    <color rgba="0.8 0.8 0.8 1.0" />
                </material>
            </collision>
            <!-- Bullet specific paramters -->
            <contact>
                <lateral_friction value="1.0" />
                <restitution value="0.5" />
            </contact>
        </link>
        <!-- END LOWER LEG LINK -->

        <joint name="${prefix}FR_HAA" type="revolute">
            <parent link="${prefix}base_link" />
            <child link="${prefix}FR_SHOULDER" />
            <limit effort="1000" lower="-10" upper="10" velocity="1000" />
            <!-- joints rotates around the x-axis -->
            <axis xyz="1 0 0" />
            <origin rpy="0 0 0" xyz="0.1946 -0.0875 0" />
            <!-- pybullet simulation parameters -->
            <dynamics damping="0.0" friction="0.0" />
        </joint>

        <link name="${prefix}FR_SHOULDER">
            <!-- TODO: Update inertias. -->
            <!-- create a dummy shoulder link to join the two joints -->
            <!-- HAA VISUAL -->
            <visual>
                <origin rpy="0 0 0" xyz="0.01950 0 0" />
                <geometry>
                    <mesh
                        filename="file://$(find solo12_description)/meshes/stl/solo12/solo12_hip_fe_fr.stl" />
                </geometry>
                <material name="grey">
                    <color rgba="0.8 0.8 0.8 1.0" />
                </material>
            </visual>
            <!-- HAA LINK COLLISION -->
            <collision>
                <origin rpy="0 0 0" xyz="0.01950 0 0" />
                <geometry>
                    <mesh
                        filename="file://$(find solo12_description)/meshes/stl/solo12/solo12_hip_fe_fr.stl" />
                </geometry>
                <material name="grey">
                    <color rgba="0.8 0.8 0.8 1.0" />
                </material>
            </collision>
            <inertial>
                <mass value="0.14853845" />
                <!-- HAA body inertia -->
                <origin rpy="0 0 0" xyz="-0.07870700 -0.01 0." />
                <inertia ixx="0.00003024" ixy="-0.00004671" ixz="0.0" iyy="0.00041193" iyz="0.0"
                    izz="0.00041107" />
            </inertial>
        </link>

        <joint name="${prefix}FR_HFE" type="revolute">
            <parent link="${prefix}FR_SHOULDER" />
            <child link="${prefix}FR_UPPER_LEG" />
            <limit effort="1000" lower="-10" upper="10" velocity="1000" />
            <!-- joints rotates around the y-axis -->
            <axis xyz="0 1 0" />
            <origin rpy="0 0 0" xyz="0 -0.014 0" />
            <!-- pybullet simulation parameters -->
            <dynamics damping="0.0" friction="0.0" />
        </joint>

        <link name="${prefix}FR_UPPER_LEG">
            <!-- Right upper leg inertia -->
            <inertial>
                <origin rpy="0 0 0" xyz="-0.00001377 -0.01935853 -0.07870700" />
                <mass value="0.14853845" />
                <inertia ixx="0.00041107" ixy="0.0" ixz="0.0" iyy="0.00041193" iyz="-0.00004671"
                    izz="0.00003024" />
            </inertial>
            <!-- UPPER LEG LINK VISUAL -->
            <visual>
                <origin rpy="0 0 0" xyz="0 0 0" />
                <geometry>
                    <mesh
                        filename="file://$(find solo12_description)/meshes/stl/with_foot/solo_upper_leg_right_side.stl" />
                </geometry>
                <material name="grey">
                    <color rgba="0.8 0.8 0.8 1.0" />
                </material>
            </visual>
            <!-- UPPER LEG LINK COLLISION -->
            <collision>
                <origin rpy="0 0 0" xyz="0 0 0" />
                <geometry>
                    <mesh
                        filename="file://$(find solo12_description)/meshes/stl/with_foot/solo_upper_leg_right_side.stl" />
                </geometry>
                <material name="grey">
                    <color rgba="0.8 0.8 0.8 1.0" />
                </material>
            </collision>
            <!-- Bullet specific paramters -->
            <contact>
                <lateral_friction value="1.0" />
                <restitution value="0.5" />
            </contact>
        </link>
        <!-- END UPPER LEG LINK -->

        <!-- KFE: Joint between the upper leg and the lower leg -->
        <joint name="${prefix}FR_KFE" type="revolute">
            <parent link="${prefix}FR_UPPER_LEG" />
            <child link="${prefix}FR_LOWER_LEG" />
            <limit effort="1000" lower="-10" upper="10" velocity="1000" />
            <!-- joints rotates around the y-axis -->
            <axis xyz="0 1 0" />
            <origin rpy="0 0 0" xyz="0 -0.03745 -0.16" />
            <!-- pybullet simulation parameters -->
            <dynamics damping="0.0" friction="0.0" />
        </joint>

        <link name="${prefix}FR_LOWER_LEG">
            <!-- Right lower leg inertia -->
            <inertial>
                <origin rpy="0 0 0" xyz="0.0 0.00787644 -0.08928215" />
                <mass value="0.03070001" />
                <inertia ixx="0.00012024" ixy="0.0" ixz="0.0" iyy="0.00012029" iyz="-0.00000305"
                    izz="0.00000216" />
            </inertial>
            <!-- LOWER LEG LINK VISUAL -->
            <visual>
                <origin rpy="0 0 0" xyz="0 0 0" />
                <geometry>
                    <mesh
                        filename="file://$(find solo12_description)/meshes/stl/with_foot/solo_lower_leg_right_side.stl" />
                </geometry>
                <material name="grey">
                    <color rgba="0.8 0.8 0.8 1.0" />
                </material>
            </visual>
            <!-- LOWER LEG LINK COLLISION -->
            <collision>
                <origin rpy="0 0 0" xyz="0 0 0" />
                <geometry>
                    <mesh
                        filename="file://$(find solo12_description)/meshes/stl/with_foot/solo_lower_leg_right_side.stl" />
                </geometry>
                <material name="grey">
                    <color rgba="0.8 0.8 0.8 1.0" />
                </material>
            </collision>
            <!-- Bullet specific paramters -->
            <contact>
                <lateral_friction value="1.0" />
                <restitution value="0.5" />
            </contact>
        </link>
        <!-- END LOWER LEG LINK -->

        <!-- KFE: Joint between the upper leg and the lower leg -->
        <joint name="${prefix}FR_ANKLE" type="fixed">
            <parent link="${prefix}FR_LOWER_LEG" />
            <child link="${prefix}FR_FOOT" />
            <origin rpy="0 0 0" xyz="0 -0.008 -0.16" />
            <!-- Limits (usefull?) -->
            <limit effort="1000" lower="-10" upper="10" velocity="1000" />
            <!-- pybullet simulation parameters -->
            <dynamics damping="0.0" friction="0.0" />
        </joint>

        <link name="${prefix}FR_FOOT">
            <!-- FOOT INERTIAL -->
            <!-- This link is symmetrical left or right -->
            <inertial>
                <origin rpy="0 0 0" xyz="0 0 0.00035767" />
                <mass value="0.00693606" />
                <inertia ixx="0.00000057" ixy="0.0" ixz="0.0" iyy="0.00000084" iyz="0.0"
                    izz="0.00000053" />
            </inertial>
            <!-- FOOT VISUAL -->
            <visual>
                <origin rpy="0 0 0" xyz="0 0 0" />
                <geometry>
                    <mesh
                        filename="file://$(find solo12_description)/meshes/stl/with_foot/solo_foot.stl" />
                </geometry>
                <material name="grey">
                    <color rgba="0.8 0.8 0.8 1.0" />
                </material>
            </visual>
            <!-- FOOT COLLISION -->
            <collision>
                <origin rpy="0 0 0" xyz="0 0 0" />
                <geometry>
                    <mesh
                        filename="file://$(find solo12_description)/meshes/stl/with_foot/solo_foot.stl" />
                </geometry>
                <material name="grey">
                    <color rgba="0.8 0.8 0.8 1.0" />
                </material>
            </collision>
            <!-- Bullet specific paramters -->
            <contact>
                <lateral_friction value="1.0" />
                <restitution value="0.5" />
            </contact>
        </link>
        <!-- END LOWER LEG LINK -->

        <joint name="${prefix}HL_HAA" type="revolute">
            <parent link="${prefix}base_link" />
            <child link="${prefix}HL_SHOULDER" />
            <limit effort="1000" lower="-10" upper="10" velocity="1000" />
            <!-- joints rotates around the x-axis -->
            <axis xyz="1 0 0" />
            <origin rpy="0 0 0" xyz="-0.1946 0.0875 0" />
            <!-- pybullet simulation parameters -->
            <dynamics damping="0.0" friction="0.0" />
        </joint>

        <link name="${prefix}HL_SHOULDER">
            <!-- TODO: Update inertias. -->
            <!-- create a dummy shoulder link to join the two joints -->
            <!-- HAA VISUAL -->
            <visual>
                <origin rpy="0 0 0" xyz="-0.01950 0 0" />
                <geometry>
                    <mesh
                        filename="file://$(find solo12_description)/meshes/stl/solo12/solo12_hip_fe_hl.stl" />
                </geometry>
                <material name="grey">
                    <color rgba="0.8 0.8 0.8 1.0" />
                </material>
            </visual>
            <!-- HAA LINK COLLISION -->
            <collision>
                <origin rpy="0 0 0" xyz="-0.01950 0 0" />
                <geometry>
                    <mesh
                        filename="file://$(find solo12_description)/meshes/stl/solo12/solo12_hip_fe_hl.stl" />
                </geometry>
                <material name="grey">
                    <color rgba="0.8 0.8 0.8 1.0" />
                </material>
            </collision>
            <inertial>
                <mass value="0.14853845" />
                <!-- HAA body inertia -->
                <origin rpy="0 0 0" xyz="0.07870700 0.01 0." />
                <inertia ixx="0.00003024" ixy="0.00004671" ixz="0.0" iyy="0.00041193" iyz="0.0"
                    izz="0.00041107" />
            </inertial>
        </link>

        <joint name="${prefix}HL_HFE" type="revolute">
            <parent link="${prefix}HL_SHOULDER" />
            <child link="${prefix}HL_UPPER_LEG" />
            <limit effort="1000" lower="-10" upper="10" velocity="1000" />
            <!-- joints rotates around the y-axis -->
            <axis xyz="0 1 0" />
            <origin rpy="0 0 0" xyz="0 0.014 0" />
            <!-- pybullet simulation parameters -->
            <dynamics damping="0.0" friction="0.0" />
        </joint>

        <link name="${prefix}HL_UPPER_LEG">
            <!-- Left upper leg inertia -->
            <inertial>
                <origin rpy="0 0 0" xyz="0.00001377 0.01935853 -0.07870700" />
                <mass value="0.14853845" />
                <inertia ixx="0.00041107" ixy="0.0" ixz="0.0" iyy="0.00041193" iyz="0.00004671"
                    izz="0.00003024" />
            </inertial>
            <!-- UPPER LEG LINK VISUAL -->
            <visual>
                <origin rpy="0 0 0" xyz="0 0 0" />
                <geometry>
                    <mesh
                        filename="file://$(find solo12_description)/meshes/stl/with_foot/solo_upper_leg_left_side.stl" />
                </geometry>
                <material name="grey">
                    <color rgba="0.8 0.8 0.8 1.0" />
                </material>
            </visual>
            <!-- UPPER LEG LINK COLLISION -->
            <collision>
                <origin rpy="0 0 0" xyz="0 0 0" />
                <geometry>
                    <mesh
                        filename="file://$(find solo12_description)/meshes/stl/with_foot/solo_upper_leg_left_side.stl" />
                </geometry>
                <material name="grey">
                    <color rgba="0.8 0.8 0.8 1.0" />
                </material>
            </collision>
            <!-- Bullet specific paramters -->
            <contact>
                <lateral_friction value="1.0" />
                <restitution value="0.5" />
            </contact>
        </link>
        <!-- END UPPER LEG LINK -->

        <!-- KFE: Joint between the upper leg and the lower leg -->
        <joint name="${prefix}HL_KFE" type="revolute">
            <parent link="${prefix}HL_UPPER_LEG" />
            <child link="${prefix}HL_LOWER_LEG" />
            <limit effort="1000" lower="-10" upper="10" velocity="1000" />
            <!-- joints rotates around the y-axis -->
            <axis xyz="0 1 0" />
            <origin rpy="0 0 0" xyz="0 0.03745 -0.16" />
            <!-- pybullet simulation parameters -->
            <dynamics damping="0.0" friction="0.0" />
        </joint>

        <link name="${prefix}HL_LOWER_LEG">
            <!-- Left lower leg inertia -->
            <inertial>
                <origin rpy="0 0 0" xyz="0.0 0.00787644 -0.08928215" />
                <mass value="0.03070001" />
                <inertia ixx="0.00012024" ixy="0.0" ixz="0.0" iyy="0.00012029" iyz="0.00000305"
                    izz="0.00000216" />
            </inertial>
            <!-- LOWER LEG LINK VISUAL -->
            <visual>
                <origin rpy="0 0 0" xyz="0 0 0" />
                <geometry>
                    <mesh
                        filename="file://$(find solo12_description)/meshes/stl/with_foot/solo_lower_leg_left_side.stl" />
                </geometry>
                <material name="grey">
                    <color rgba="0.8 0.8 0.8 1.0" />
                </material>
            </visual>
            <!-- LOWER LEG LINK COLLISION -->
            <collision>
                <origin rpy="0 0 0" xyz="0 0 0" />
                <geometry>
                    <mesh
                        filename="file://$(find solo12_description)/meshes/stl/with_foot/solo_lower_leg_left_side.stl" />
                </geometry>
                <material name="grey">
                    <color rgba="0.8 0.8 0.8 1.0" />
                </material>
            </collision>
            <!-- Bullet specific paramters -->
            <contact>
                <lateral_friction value="1.0" />
                <restitution value="0.5" />
            </contact>
        </link>
        <!-- END LOWER LEG LINK -->

        <!-- KFE: Joint between the upper leg and the lower leg -->
        <joint name="${prefix}HL_ANKLE" type="fixed">
            <parent link="${prefix}HL_LOWER_LEG" />
            <child link="${prefix}HL_FOOT" />
            <origin rpy="0 0 0" xyz="0 0.008 -0.16" />
            <!-- Limits (usefull?) -->
            <limit effort="1000" lower="-10" upper="10" velocity="1000" />
            <!-- pybullet simulation parameters -->
            <dynamics damping="0.0" friction="0.0" />
        </joint>

        <link name="${prefix}HL_FOOT">
            <!-- FOOT INERTIAL -->
            <!-- This link is symmetrical left or right -->
            <inertial>
                <origin rpy="0 0 0" xyz="0 0 0.00035767" />
                <mass value="0.00693606" />
                <inertia ixx="0.00000057" ixy="0.0" ixz="0.0" iyy="0.00000084" iyz="0.0"
                    izz="0.00000053" />
            </inertial>
            <!-- FOOT VISUAL -->
            <visual>
                <origin rpy="0 0 0" xyz="0 0 0" />
                <geometry>
                    <mesh
                        filename="file://$(find solo12_description)/meshes/stl/with_foot/solo_foot.stl" />
                </geometry>
                <material name="grey">
                    <color rgba="0.8 0.8 0.8 1.0" />
                </material>
            </visual>
            <!-- FOOT COLLISION -->
            <collision>
                <origin rpy="0 0 0" xyz="0 0 0" />
                <geometry>
                    <mesh
                        filename="file://$(find solo12_description)/meshes/stl/with_foot/solo_foot.stl" />
                </geometry>
                <material name="grey">
                    <color rgba="0.8 0.8 0.8 1.0" />
                </material>
            </collision>
            <!-- Bullet specific paramters -->
            <contact>
                <lateral_friction value="1.0" />
                <restitution value="0.5" />
            </contact>
        </link>
        <!-- END LOWER LEG LINK -->

        <joint name="${prefix}HR_HAA" type="revolute">
            <parent link="${prefix}base_link" />
            <child link="${prefix}HR_SHOULDER" />
            <limit effort="1000" lower="-10" upper="10" velocity="1000" />
            <!-- joints rotates around the x-axis -->
            <axis xyz="1 0 0" />
            <origin rpy="0 0 0" xyz="-0.1946 -0.0875 0" />
            <!-- pybullet simulation parameters -->
            <dynamics damping="0.0" friction="0.0" />
        </joint>

        <link name="${prefix}HR_SHOULDER">
            <!-- TODO: Update inertias. -->
            <!-- create a dummy shoulder link to join the two joints -->
            <!-- HAA VISUAL -->
            <visual>
                <origin rpy="0 0 0" xyz="-0.01950 0 0" />
                <geometry>
                    <mesh
                        filename="file://$(find solo12_description)/meshes/stl/solo12/solo12_hip_fe_hr.stl" />
                </geometry>
                <material name="grey">
                    <color rgba="0.8 0.8 0.8 1.0" />
                </material>
            </visual>
            <!-- HAA LINK COLLISION -->
            <collision>
                <origin rpy="0 0 0" xyz="-0.01950 0 0" />
                <geometry>
                    <mesh
                        filename="file://$(find solo12_description)/meshes/stl/solo12/solo12_hip_fe_hr.stl" />
                </geometry>
                <material name="grey">
                    <color rgba="0.8 0.8 0.8 1.0" />
                </material>
            </collision>
            <inertial>
                <mass value="0.14853845" />
                <!-- HAA body inertia -->
                <origin rpy="0 0 0" xyz="0.07870700 -0.01 0." />
                <inertia ixx="0.00003024" ixy="-0.00004671" ixz="0.0" iyy="0.00041193" iyz="0.0"
                    izz="0.00041107" />
            </inertial>
        </link>

        <joint name="${prefix}HR_HFE" type="revolute">
            <parent link="${prefix}HR_SHOULDER" />
            <child link="${prefix}HR_UPPER_LEG" />
            <limit effort="1000" lower="-10" upper="10" velocity="1000" />
            <!-- joints rotates around the y-axis -->
            <axis xyz="0 1 0" />
            <origin rpy="0 0 0" xyz="0 -0.014 0" />
            <!-- pybullet simulation parameters -->
            <dynamics damping="0.0" friction="0.0" />
        </joint>

        <link name="${prefix}HR_UPPER_LEG">
            <!-- Right upper leg inertia -->
            <inertial>
                <origin rpy="0 0 0" xyz="-0.00001377 -0.01935853 -0.07870700" />
                <mass value="0.14853845" />
                <inertia ixx="0.00041107" ixy="0.0" ixz="0.0" iyy="0.00041193" iyz="-0.00004671"
                    izz="0.00003024" />
            </inertial>
            <!-- UPPER LEG LINK VISUAL -->
            <visual>
                <origin rpy="0 0 0" xyz="0 0 0" />
                <geometry>
                    <mesh
                        filename="file://$(find solo12_description)/meshes/stl/with_foot/solo_upper_leg_right_side.stl" />
                </geometry>
                <material name="grey">
                    <color rgba="0.8 0.8 0.8 1.0" />
                </material>
            </visual>
            <!-- UPPER LEG LINK COLLISION -->
            <collision>
                <origin rpy="0 0 0" xyz="0 0 0" />
                <geometry>
                    <mesh
                        filename="file://$(find solo12_description)/meshes/stl/with_foot/solo_upper_leg_right_side.stl" />
                </geometry>
                <material name="grey">
                    <color rgba="0.8 0.8 0.8 1.0" />
                </material>
            </collision>
            <!-- Bullet specific paramters -->
            <contact>
                <lateral_friction value="1.0" />
                <restitution value="0.5" />
            </contact>
        </link>
        <!-- END UPPER LEG LINK -->

        <!-- KFE: Joint between the upper leg and the lower leg -->
        <joint name="${prefix}HR_KFE" type="revolute">
            <parent link="${prefix}HR_UPPER_LEG" />
            <child link="${prefix}HR_LOWER_LEG" />
            <limit effort="1000" lower="-10" upper="10" velocity="1000" />
            <!-- joints rotates around the y-axis -->
            <axis xyz="0 1 0" />
            <origin rpy="0 0 0" xyz="0 -0.03745 -0.16" />
            <!-- pybullet simulation parameters -->
            <dynamics damping="0.0" friction="0.0" />
        </joint>

        <link name="${prefix}HR_LOWER_LEG">
            <!-- Right lower leg inertia -->
            <inertial>
                <origin rpy="0 0 0" xyz="0.0 0.00787644 -0.08928215" />
                <mass value="0.03070001" />
                <inertia ixx="0.00012024" ixy="0.0" ixz="0.0" iyy="0.00012029" iyz="-0.00000305"
                    izz="0.00000216" />
            </inertial>
            <!-- LOWER LEG LINK VISUAL -->
            <visual>
                <origin rpy="0 0 0" xyz="0 0 0" />
                <geometry>
                    <mesh
                        filename="file://$(find solo12_description)/meshes/stl/with_foot/solo_lower_leg_right_side.stl" />
                </geometry>
                <material name="grey">
                    <color rgba="0.8 0.8 0.8 1.0" />
                </material>
            </visual>
            <!-- LOWER LEG LINK COLLISION -->
            <collision>
                <origin rpy="0 0 0" xyz="0 0 0" />
                <geometry>
                    <mesh
                        filename="file://$(find solo12_description)/meshes/stl/with_foot/solo_lower_leg_right_side.stl" />
                </geometry>
                <material name="grey">
                    <color rgba="0.8 0.8 0.8 1.0" />
                </material>
            </collision>
            <!-- Bullet specific paramters -->
            <contact>
                <lateral_friction value="1.0" />
                <restitution value="0.5" />
            </contact>
        </link>
        <!-- END LOWER LEG LINK -->

        <!-- KFE: Joint between the upper leg and the lower leg -->
        <joint name="${prefix}HR_ANKLE" type="fixed">
            <parent link="${prefix}HR_LOWER_LEG" />
            <child link="${prefix}HR_FOOT" />
            <origin rpy="0 0 0" xyz="0 -0.008 -0.16" />
            <!-- Limits (usefull?) -->
            <limit effort="1000" lower="-10" upper="10" velocity="1000" />
            <!-- pybullet simulation parameters -->
            <dynamics damping="0.0" friction="0.0" />
        </joint>

        <link name="${prefix}HR_FOOT">
            <!-- FOOT INERTIAL -->
            <!-- This link is symmetrical left or right -->
            <inertial>
                <origin rpy="0 0 0" xyz="0 0 0.00035767" />
                <mass value="0.00693606" />
                <inertia ixx="0.00000057" ixy="0.0" ixz="0.0" iyy="0.00000084" iyz="0.0"
                    izz="0.00000053" />
            </inertial>
            <!-- FOOT VISUAL -->
            <visual>
                <origin rpy="0 0 0" xyz="0 0 0" />
                <geometry>
                    <mesh
                        filename="file://$(find solo12_description)/meshes/stl/with_foot/solo_foot.stl" />
                </geometry>
                <material name="grey">
                    <color rgba="0.8 0.8 0.8 1.0" />
                </material>
            </visual>
            <!-- FOOT COLLISION -->
            <collision>
                <origin rpy="0 0 0" xyz="0 0 0" />
                <geometry>
                    <mesh
                        filename="file://$(find solo12_description)/meshes/stl/with_foot/solo_foot.stl" />
                </geometry>
                <material name="grey">
                    <color rgba="0.8 0.8 0.8 1.0" />
                </material>
            </collision>
            <!-- Bullet specific paramters -->
            <contact>
                <lateral_friction value="1.0" />
                <restitution value="0.5" />
            </contact>
        </link>
        <!-- END LOWER LEG LINK -->

    </xacro:macro>

</robot>